<sdf version='1.9'>
  <model name='Baxter'>
    <pose>0 0 0 0 0 0</pose>
    <link name='base_link'>
      <pose relative_to='__model__'>0 0 0.93 0 -0 0</pose>
        <visual name='visual'>
          <geometry>
            <mesh>
              <uri>file://models/baxter/meshes/PEDESTAL.DAE</uri>
            </mesh>
          </geometry>
        </visual>
        <collision name='base_collision'>
          <geometry>
            <mesh>
              <uri>file://models/baxter/meshes/PEDESTAL.DAE</uri>
            </mesh>
          </geometry>
        </collision>
      </link>
      <link name='body'>
        <pose relative_to='base_link'>0 0 0 0 0 0</pose>
        <visual name='visual'>
          <geometry>
            <mesh>
              <uri>file://models/baxter/meshes/base_link.DAE</uri>
            </mesh>
          </geometry>
        </visual>
        <collision name='body_collision'>
          <geometry>
            <mesh>
              <uri>file://models/baxter/meshes/base_link.DAE</uri>
            </mesh>
          </geometry>
        </collision>
        <inertial>
          <mass>1</mass>
          <inertia>
            <ixx>1</ixx>
            <ixy>0</ixy>
            <ixz>0</ixz>
            <iyy>1</iyy>
            <iyz>0</iyz>
            <izz>1</izz>
          </inertia>
        </inertial>
      </link>
      <link name='chin'>
        <pose relative_to='base_link'>0.065 0 0.685 0 0 0</pose>
        <visual name='visual'>
          <geometry>
            <mesh>
              <uri>file://models/baxter/meshes/H0.DAE</uri>
            </mesh>
          </geometry>
        </visual>
        <collision name='chin_collision'>
          <geometry>
            <mesh>
              <uri>file://models/baxter/meshes/H0.DAE</uri>
            </mesh>
          </geometry>
        </collision>
        <inertial>
          <mass>1</mass>
          <inertia>
            <ixx>1</ixx>
            <ixy>0</ixy>
            <ixz>0</ixz>
            <iyy>1</iyy>
            <iyz>0</iyz>
            <izz>1</izz>
          </inertia>
        </inertial>
      </link>
      <link name='head'>
        <pose relative_to='base_link'>0.15 -0 0.69 1.5 -0.3 -0</pose>
        <visual name='visual'>
          <geometry>
            <mesh>
              <uri>file://models/baxter/meshes/H1.DAE</uri>
            </mesh>
          </geometry>
        </visual>
        <collision name='head_collision'>
          <geometry>
            <mesh>
              <uri>file://models/baxter/meshes/H1.DAE</uri>
            </mesh>
          </geometry>
        </collision>
        <inertial>
          <mass>1</mass>
          <inertia>
            <ixx>1</ixx>
            <ixy>0</ixy>
            <ixz>0</ixz>
            <iyy>1</iyy>
            <iyz>0</iyz>
            <izz>1</izz>
          </inertia>
        </inertial>
      </link>
      <joint name='body_joint' type='fixed'>
			  <parent>base_link</parent>
			  <child>body</child>
		  </joint>
      <joint name='chin_joint' type='revolute'>
			  <parent>body</parent>
			  <child>chin</child>
			<axis>
				<xyz>0 0 1</xyz>
				<limit>
				  <upper>1</upper>
				  <lower>-1</lower>
				</limit>
			</axis>		      
		  </joint>
		  <joint name='head_joint' type='revolute'>
			  <parent>chin</parent>
			  <child>head</child>
			  <axis>
			    <xyz>0 0 1</xyz>
			    <limit>
			      <upper>0.1</upper>
			      <lower>-0.5</lower>
			    </limit>
			  </axis>
		  </joint>
		  	  <link name='camera_body'>
		  <pose relative_to='head'>0.055 0.08 0 0 0 0</pose>
		  <visual name='visual'>
			  <pose>0 0 0 0 0 0</pose>
			  <geometry>
				  <cylinder>
					  <radius>0.01</radius>
					  <length>0.01</length>
				  </cylinder>
			  </geometry>
		  </visual>
		  <sensor name="camera" type="camera">
			  <camera>
				  <pose>0 0 0 0 0 0</pose>
				  <horizontal_fov>1.047</horizontal_fov>
				  <image>
					  <width>800</width>
					  <height>600</height>
				  </image>
				  <clip>
					  <near>0.1</near>
					  <far>100</far>
				  </clip>
				  <optical_frame_id>camera</optical_frame_id>
			  </camera>
			  <always_on>1</always_on>
			  <update_rate>30</update_rate>
			  <visualize>true</visualize>
			  <topic>camera</topic>
		  </sensor>
	  </link>
	  <link name='camera'>
		  <pose relative_to="camera_body">0.01 0 0 1.5708 3.141 1.5708</pose>
	  </link>
	  <joint name='camera_optical_joint' type='fixed'>
		  <parent>camera_body</parent>
		  <child>camera</child>
	  </joint>
	  <joint name='camera_to_head' type='fixed'>
		  <parent>head</parent>
		  <child>camera_body</child>
	  </joint>
  </model>
</sdf>
