<sdf version='1.9'>
  <world name='empty'>
    <physics name='1ms' type='ignored'>
      <max_step_size>0.001</max_step_size>
      <real_time_factor>1</real_time_factor>
      <real_time_update_rate>1000</real_time_update_rate>
    </physics>
    <plugin name='gz::sim::systems::Physics' filename='ignition-gazebo-physics-system'/>
    <plugin name='gz::sim::systems::UserCommands' filename='ignition-gazebo-user-commands-system'/>
    <plugin name='gz::sim::systems::SceneBroadcaster' filename='ignition-gazebo-scene-broadcaster-system'/>
    <plugin name='gz::sim::systems::Contact' filename='ignition-gazebo-contact-system'/>
    <gravity>0 0 -9.8</gravity>
    <magnetic_field>6e-06 2.3e-05 -4.2e-05</magnetic_field>
    <atmosphere type='adiabatic'/>
    <scene>
      <ambient>0.4 0.4 0.4 1</ambient>
      <background>0.7 0.7 0.7 1</background>
      <shadows>true</shadows>
    </scene>
    <model name='ground_plane'>
      <static>true</static>
      <link name='link'>
        <collision name='collision'>
          <geometry>
            <plane>
              <normal>0 0 1</normal>
              <size>100 100</size>
            </plane>
          </geometry>
          <surface>
            <friction>
              <ode/>
            </friction>
            <bounce/>
            <contact/>
          </surface>
        </collision>
        <visual name='visual'>
          <geometry>
            <plane>
              <normal>0 0 1</normal>
              <size>100 100</size>
            </plane>
          </geometry>
          <material>
            <ambient>0.8 0.8 0.8 1</ambient>
            <diffuse>0.8 0.8 0.8 1</diffuse>
            <specular>0.8 0.8 0.8 1</specular>
          </material>
        </visual>
        <pose>0 0 0 0 -0 0</pose>
        <inertial>
          <pose>0 0 0 0 -0 0</pose>
          <mass>1</mass>
          <inertia>
            <ixx>1</ixx>
            <ixy>0</ixy>
            <ixz>0</ixz>
            <iyy>1</iyy>
            <iyz>0</iyz>
            <izz>1</izz>
          </inertia>
        </inertial>
        <enable_wind>false</enable_wind>
      </link>
      <pose>0 0 0 0 -0 0</pose>
      <self_collide>false</self_collide>
    </model>
    <model name='Baxter'>
      <pose relative_to='ground_plane'>0 0 0 0 0 0</pose>
      <link name='body'>
        <pose relative_to='__model__'>0 0 0.93 0 0 0</pose>
        <visual name='visual'>
          <geometry>
            <mesh>
              <uri>file:/meshes/base_link.DAE</uri>
            </mesh>
          </geometry>
        </visual>
        <collision name='body_collision'>
          <geometry>
            <mesh>
              <uri>file:/meshes/base_link.DAE</uri>
            </mesh>
          </geometry>
        </collision>
        <inertial>
          <mass>1</mass>
          <inertia>
            <ixx>1</ixx>
            <ixy>0</ixy>
            <ixz>0</ixz>
            <iyy>1</iyy>
            <iyz>0</iyz>
            <izz>1</izz>
          </inertia>
        </inertial>
      </link>
      <link name='head'>
        <pose relative_to='__model__'>0.15 -0 1.62 1.5 -0.3 -0</pose>
        <visual name='visual'>
          <geometry>
            <mesh>
              <uri>file:/meshes/H1.DAE</uri>
            </mesh>
          </geometry>
        </visual>
        <collision name='head_collision'>
          <geometry>
            <mesh>
              <uri>file:/meshes/H1.DAE</uri>
            </mesh>
          </geometry>
        </collision>
        <inertial>
          <mass>1</mass>
          <inertia>
            <ixx>1</ixx>
            <ixy>0</ixy>
            <ixz>0</ixz>
            <iyy>1</iyy>
            <iyz>0</iyz>
            <izz>1</izz>
          </inertia>
        </inertial>
      </link>
      <link name='base'>
        <pose relative_to='__model__'>0 0 0.93 0 -0 0</pose>
        <visual name='visual'>
          <geometry>
            <mesh>
              <uri>file:/meshes/PEDESTAL.DAE</uri>
            </mesh>
          </geometry>
        </visual>
        <collision name='base_collision'>
          <geometry>
            <mesh>
              <uri>file:/meshes/PEDESTAL.DAE</uri>
            </mesh>
          </geometry>
        </collision>
        <pose>0 0 0 0 -0 0</pose>
        <inertial>
          <pose>0 0 0 0 -0 0</pose>
          <mass>1</mass>
          <inertia>
            <ixx>1</ixx>
            <ixy>0</ixy>
            <ixz>0</ixz>
            <iyy>1</iyy>
            <iyz>0</iyz>
            <izz>1</izz>
          </inertia>
        </inertial>
      </link>
      <link name='chin'>
        <pose relative_to='__model__'>0.065 0 1.615 0 -0 0</pose>
        <visual name='visual'>
          <geometry>
            <mesh>y
              <uri>file:/meshes/H0.DAE</uri>
            </mesh>
          </geometry>
        </visual>
        <collision name='chin_collision'>
          <geometry>
            <mesh>
              <uri>file:/meshes/H0.DAE</uri>
            </mesh>
          </geometry>
        </collision>
        <pose>0 0 0 0 -0 0</pose>
        <inertial>
          <pose>0 0 0 0 -0 0</pose>
          <mass>1</mass>
          <inertia>
            <ixx>1</ixx>
            <ixy>0</ixy>
            <ixz>0</ixz>
            <iyy>1</iyy>
            <iyz>0</iyz>
            <izz>1</izz>
          </inertia>
        </inertial>
      </link>
      <joint name='chin_joint' type='revolute'>
			<pose relative_to='chin'/>
			<parent>body</parent>
			<child>chin</child>
			<axis>
			<xyz expressed_in='__model__'>0 0 1</xyz> <!--can be defined as any frame or even arbitrary frames-->
			<limit>
			    <lower>-1.79769e+308</lower>    <!--negative infinity-->
			    <upper>1.79769e+308</upper>     <!--positive infinity-->
			</limit>
		    </axis>
		</joint>
		<joint name='body_to_base' type='fixed'>
			<pose relative_to='body'/>
			<parent>base</parent>
			<child>body</child>
			<axis>
			<xyz expressed_in='__model__'>0 0 1</xyz> <!--can be defined as any frame or even arbitrary frames-->
		    </axis>
		</joint>
		<joint name='head_joint' type='revolute'>
			<pose relative_to='head'/>
			<parent>chin</parent>
			<child>head</child>
			<axis>
			<xyz expressed_in='__model__'>0 1 0</xyz> <!--can be defined as any frame or even arbitrary frames-->
			<limit>
			    <lower>-1.79769e+308</lower>    <!--negative infinity-->
			    <upper>1.79769e+308</upper>     <!--positive infinity-->
			</limit>
		    </axis>
		</joint>
	<link name='camera_body'>
		<pose relative_to='head'>0.055 0.08 0 0 0 0</pose>
		<visual name='visual'>
			<pose>0 0 0 0 0 0</pose>
			<geometry>
				<cylinder>
					<radius>0.01</radius>
					<length>0.01</length>
				</cylinder>
			</geometry>
		</visual>
		<sensor name="camera" type="camera">
			<camera>
				<pose>0 0 0 0 0 0</pose>
				<horizontal_fov>1.047</horizontal_fov>
				<image>
					<width>800</width>
					<height>600</height>
				</image>
				<clip>
					<near>0.1</near>
					<far>100</far>
				</clip>
				<optical_frame_id>camera</optical_frame_id>
			</camera>
			<always_on>1</always_on>
			<update_rate>30</update_rate>
			<visualize>true</visualize>
			<topic>camera</topic>
		</sensor>
	</link>
	<link name='camera'>
		<pose relative_to="camera_body">0.01 0 0 1.5708 3.141 1.5708</pose>
	</link>
	<joint name='camera_optical_joint' type='fixed'>
		<parent>camera_body</parent>
		<child>camera</child>
	</joint>
	<joint name='camera_to_head' type='fixed'>
		<parent>head</parent>
		<child>camera_body</child>
	</joint>
    </model>
    <light name='sun' type='directional'>
      <pose>0 0 10 0 -0 0</pose>
      <cast_shadows>true</cast_shadows>
      <intensity>1</intensity>
      <direction>-0.5 0.1 -0.9</direction>
      <diffuse>0.8 0.8 0.8 1</diffuse>
      <specular>0.2 0.2 0.2 1</specular>
      <attenuation>
        <range>1000</range>
        <linear>0.01</linear>
        <constant>0.90000000000000002</constant>
        <quadratic>0.001</quadratic>
      </attenuation>
      <spot>
        <inner_angle>0</inner_angle>
        <outer_angle>0</outer_angle>
        <falloff>0</falloff>
      </spot>
    </light>
  </world>
</sdf>
